<?xml version="1.0" encoding="utf-8"?>
<!-- This URDF was automatically created by SolidWorks to URDF Exporter! Originally created by Stephen Brawner (brawner@gmail.com) 
     Commit Version: 1.6.0-4-g7f85cfe  Build Version: 1.6.7995.38578
     For more information, please see http://wiki.ros.org/sw_urdf_exporter -->
<robot
  name="CB02_URDF(ECS)130C">
<mujoco>
  <compiler meshdir="../meshes/" balanceinertia="true" discardvisual="false"/>
</mujoco>
  <link
    name="base_link">
    <inertial>
      <origin
        xyz="0.000723 4.364E-05 0.059255"
        rpy="0 0 0" />
      <mass
        value="4.7364" />
      <inertia
        ixx="0.014859"
        ixy="5.75E-06"
        ixz="4.18E-06"
        iyy="0.010209"
        iyz="4.58E-06"
        izz="0.012669" />
    </inertial>
    <visual>
      <origin
        xyz="0 0 0"
        rpy="0 0 0" />
      <geometry>
        <mesh
          filename="../meshes/base_link.STL" />
      </geometry>
      <material
        name="">
        <color
          rgba="0.79216 0.81961 0.93333 1" />
      </material>
    </visual>
    <collision>
      <origin
        xyz="0 0 0"
        rpy="0 0 0" />
      <geometry>
        <mesh
          filename="../meshes/base_link.STL" />
      </geometry>
    </collision>
  </link>
  <link
    name="left_leg_pelvic_pitch_link">
    <inertial>
      <origin
        xyz="0.007392 0.073579 -0.047622"
        rpy="0 0 0" />
      <mass
        value="2.1671" />
      <inertia
        ixx="0.0038978"
        ixy="-2.998E-05"
        ixz="8.411E-05"
        iyy="0.0025035"
        iyz="-0.00071248"
        izz="0.0026698" />
    </inertial>
    <visual>
      <origin
        xyz="0 0 0"
        rpy="0 0 0" />
      <geometry>
        <mesh
          filename="../meshes/left_leg_pelvic_pitch_link.STL" />
      </geometry>
      <material
        name="">
        <color
          rgba="0.79216 0.81961 0.93333 1" />
      </material>
    </visual>
    <collision>
      <origin
        xyz="0 0 0"
        rpy="0 0 0" />
      <geometry>
        <mesh
          filename="../meshes/left_leg_pelvic_pitch_link.STL" />
      </geometry>
    </collision>
  </link>
  <joint
    name="left_leg_pelvic_pitch_joint"
    type="revolute">
    <origin
      xyz="0 0.061 0.0575"
      rpy="0 0 0" />
    <parent
      link="base_link" />
    <child
      link="left_leg_pelvic_pitch_link" />
    <axis
      xyz="0 1 0" />
    <limit
      lower="-1.9199"
      upper="1.5708"
      effort="150"
      velocity="14" />
  </joint>
  <link
    name="left_leg_pelvic_roll_link">
    <inertial>
      <origin
        xyz="0.024639 0.00080539 -0.053958"
        rpy="0 0 0" />
      <mass
        value="0.72933" />
      <inertia
        ixx="0.0019449"
        ixy="8.56E-06"
        ixz="0.00055534"
        iyy="0.0021761"
        iyz="2.152E-05"
        izz="0.0013377" />
    </inertial>
    <visual>
      <origin
        xyz="0 0 0"
        rpy="0 0 0" />
      <geometry>
        <mesh
          filename="../meshes/left_leg_pelvic_roll_link.STL" />
      </geometry>
      <material
        name="">
        <color
          rgba="0.79216 0.81961 0.93333 1" />
      </material>
    </visual>
    <collision>
      <origin
        xyz="0 0 0"
        rpy="0 0 0" />
      <geometry>
        <mesh
          filename="../meshes/left_leg_pelvic_roll_link.STL" />
      </geometry>
    </collision>
  </link>
  <joint
    name="left_leg_pelvic_roll_joint"
    type="revolute">
    <origin
      xyz="-0.0028 0.0815 -0.055"
      rpy="0 0 0" />
    <parent
      link="left_leg_pelvic_pitch_link" />
    <child
      link="left_leg_pelvic_roll_link" />
    <axis
      xyz="1 0 0" />
    <limit
      lower="-0.17453"
      upper="1.5708"
      effort="150"
      velocity="14" />
  </joint>
  <link
    name="left_leg_pelvic_yaw_link">
    <inertial>
      <origin
        xyz="-0.0066188 0.0024439 -0.16689"
        rpy="0 0 0" />
      <mass
        value="4.1415" />
      <inertia
        ixx="0.058172"
        ixy="-0.00030409"
        ixz="0.0038198"
        iyy="0.059636"
        iyz="-0.0012251"
        izz="0.0060704" />
    </inertial>
    <visual>
      <origin
        xyz="0 0 0"
        rpy="0 0 0" />
      <geometry>
        <mesh
          filename="../meshes/left_leg_pelvic_yaw_link.STL" />
      </geometry>
      <material
        name="">
        <color
          rgba="0.79216 0.81961 0.93333 1" />
      </material>
    </visual>
    <collision>
      <origin
        xyz="0 0 0"
        rpy="0 0 0" />
      <geometry>
        <mesh
          filename="../meshes/left_leg_pelvic_yaw_link.STL" />
      </geometry>
    </collision>
  </link>
  <joint
    name="left_leg_pelvic_yaw_joint"
    type="revolute">
    <origin
      xyz="0 0 -0.0975"
      rpy="0 0 0" />
    <parent
      link="left_leg_pelvic_roll_link" />
    <child
      link="left_leg_pelvic_yaw_link" />
    <axis
      xyz="0 0 1" />
    <limit
      lower="-1.5708"
      upper="1.5708"
      effort="60"
      velocity="14" />
  </joint>
  <link
    name="left_leg_knee_pitch_link">
    <inertial>
      <origin
        xyz="0.0062969 -0.0031691 -0.19469"
        rpy="0 0 0" />
      <mass
        value="4.2951" />
      <inertia
        ixx="0.054032"
        ixy="0.00011774"
        ixz="0.0018449"
        iyy="0.054471"
        iyz="-0.0022958"
        izz="0.0056905" />
    </inertial>
    <visual>
      <origin
        xyz="0 0 0"
        rpy="0 0 0" />
      <geometry>
        <mesh
          filename="../meshes/left_leg_knee_pitch_link.STL" />
      </geometry>
      <material
        name="">
        <color
          rgba="0.79216 0.81961 0.93333 1" />
      </material>
    </visual>
    <collision>
      <origin
        xyz="0 0 0"
        rpy="0 0 0" />
      <geometry>
        <mesh
          filename="../meshes/left_leg_knee_pitch_link.STL" />
      </geometry>
    </collision>
  </link>
  <joint
    name="left_leg_knee_pitch_joint"
    type="revolute">
    <origin
      xyz="-0.02 0 -0.2735"
      rpy="0 0 0" />
    <parent
      link="left_leg_pelvic_yaw_link" />
    <child
      link="left_leg_knee_pitch_link" />
    <axis
      xyz="0 1 0" />
    <limit
      lower="0"
      upper="2.5307"
      effort="150"
      velocity="14" />
  </joint>
  <link
    name="left_leg_ankle_pitch_link">
    <inertial>
      <origin
        xyz="0 -1.93E-06 0"
        rpy="0 0 0" />
      <mass
        value="0.057376" />
      <inertia
        ixx="1.172E-05"
        ixy="0"
        ixz="0"
        iyy="9.47E-06"
        iyz="0"
        izz="1.044E-05" />
    </inertial>
    <visual>
      <origin
        xyz="0 0 0"
        rpy="0 0 0" />
      <geometry>
        <mesh
          filename="../meshes/left_leg_ankle_pitch_link.STL" />
      </geometry>
      <material
        name="">
        <color
          rgba="0.79216 0.81961 0.93333 1" />
      </material>
    </visual>
    <collision>
      <origin
        xyz="0 0 0"
        rpy="0 0 0" />
      <geometry>
        <mesh
          filename="../meshes/left_leg_ankle_pitch_link.STL" />
      </geometry>
    </collision>
  </link>
  <joint
    name="left_leg_ankle_pitch_joint"
    type="revolute">
    <origin
      xyz="0 0 -0.453"
      rpy="0 0 0" />
    <parent
      link="left_leg_knee_pitch_link" />
    <child
      link="left_leg_ankle_pitch_link" />
    <axis
      xyz="0 1 0" />
    <limit
      lower="-0.87266"
      upper="0.50614"
      effort="60"
      velocity="14" />
  </joint>
  <link
    name="left_leg_ankle_roll_link">
    <inertial>
      <origin
        xyz="0.022729 0.0012472 -0.036097"
        rpy="0 0 0" />
      <mass
        value="1.1006" />
      <inertia
        ixx="0.0014689"
        ixy="0.00010055"
        ixz="-0.00028119"
        iyy="0.0058057"
        iyz="-1.06E-05"
        izz="0.0062384" />
    </inertial>
    <visual>
      <origin
        xyz="0 0 0"
        rpy="0 0 0" />
      <geometry>
        <mesh
          filename="../meshes/left_leg_ankle_roll_link.STL" />
      </geometry>
      <material
        name="">
        <color
          rgba="0.79216 0.81961 0.93333 1" />
      </material>
    </visual>
    <collision>
      <origin
        xyz="0 0 0"
        rpy="0 0 0" />
      <geometry>
        <mesh
          filename="../meshes/left_leg_ankle_roll_link.STL" />
      </geometry>
    </collision>
  </link>
  <joint
    name="left_leg_ankle_roll_joint"
    type="revolute">
    <origin
      xyz="0 0 0"
      rpy="0 0 0" />
    <parent
      link="left_leg_ankle_pitch_link" />
    <child
      link="left_leg_ankle_roll_link" />
    <axis
      xyz="1 0 0" />
    <limit
      lower="-0.50614"
      upper="0.50614"
      effort="60"
      velocity="14" />
  </joint>
  <link
    name="right_leg_pelvic_pitch_link">
    <inertial>
      <origin
        xyz="0.0073684 -0.073515 -0.047566"
        rpy="0 0 0" />
      <mass
        value="2.1692" />
      <inertia
        ixx="0.0039156"
        ixy="2.66E-05"
        ixz="8.106E-05"
        iyy="0.0025133"
        iyz="0.00072134"
        izz="0.0026803" />
    </inertial>
    <visual>
      <origin
        xyz="0 0 0"
        rpy="0 0 0" />
      <geometry>
        <mesh
          filename="../meshes/right_leg_pelvic_pitch_link.STL" />
      </geometry>
      <material
        name="">
        <color
          rgba="0.79216 0.81961 0.93333 1" />
      </material>
    </visual>
    <collision>
      <origin
        xyz="0 0 0"
        rpy="0 0 0" />
      <geometry>
        <mesh
          filename="../meshes/right_leg_pelvic_pitch_link.STL" />
      </geometry>
    </collision>
  </link>
  <joint
    name="right_leg_pelvic_pitch_joint"
    type="revolute">
    <origin
      xyz="0 -0.061 0.0575"
      rpy="0 0 0" />
    <parent
      link="base_link" />
    <child
      link="right_leg_pelvic_pitch_link" />
    <axis
      xyz="0 1 0" />
    <limit
      lower="-1.9199"
      upper="1.5708"
      effort="150"
      velocity="14" />
  </joint>
  <link
    name="right_leg_pelvic_roll_link">
    <inertial>
      <origin
        xyz="0.024541 -0.00073527 -0.053979"
        rpy="0 0 0" />
      <mass
        value="0.73064" />
      <inertia
        ixx="0.0019453"
        ixy="-1.075E-05"
        ixz="0.00055616"
        iyy="0.0021802"
        iyz="-3.349E-05"
        izz="0.0013419" />
    </inertial>
    <visual>
      <origin
        xyz="0 0 0"
        rpy="0 0 0" />
      <geometry>
        <mesh
          filename="../meshes/right_leg_pelvic_roll_link.STL" />
      </geometry>
      <material
        name="">
        <color
          rgba="0.79216 0.81961 0.93333 1" />
      </material>
    </visual>
    <collision>
      <origin
        xyz="0 0 0"
        rpy="0 0 0" />
      <geometry>
        <mesh
          filename="../meshes/right_leg_pelvic_roll_link.STL" />
      </geometry>
    </collision>
  </link>
  <joint
    name="right_leg_pelvic_roll_joint"
    type="revolute">
    <origin
      xyz="-0.0028 -0.0815 -0.055"
      rpy="0 0 0" />
    <parent
      link="right_leg_pelvic_pitch_link" />
    <child
      link="right_leg_pelvic_roll_link" />
    <axis
      xyz="1 0 0" />
    <limit
      lower="-1.5708"
      upper="0.17453"
      effort="150"
      velocity="14" />
  </joint>
  <link
    name="right_leg_pelvic_yaw_link">
    <inertial>
      <origin
        xyz="-0.006618 -0.0023786 -0.16685"
        rpy="0 0 0" />
      <mass
        value="4.1427" />
      <inertia
        ixx="0.058213"
        ixy="0.00029196"
        ixz="0.0038117"
        iyy="0.059671"
        iyz="0.0012683"
        izz="0.0060747" />
    </inertial>
    <visual>
      <origin
        xyz="0 0 0"
        rpy="0 0 0" />
      <geometry>
        <mesh
          filename="../meshes/right_leg_pelvic_yaw_link.STL" />
      </geometry>
      <material
        name="">
        <color
          rgba="0.79216 0.81961 0.93333 1" />
      </material>
    </visual>
    <collision>
      <origin
        xyz="0 0 0"
        rpy="0 0 0" />
      <geometry>
        <mesh
          filename="../meshes/right_leg_pelvic_yaw_link.STL" />
      </geometry>
    </collision>
  </link>
  <joint
    name="right_leg_pelvic_yaw_joint"
    type="revolute">
    <origin
      xyz="0 0 -0.0975"
      rpy="0 0 0" />
    <parent
      link="right_leg_pelvic_roll_link" />
    <child
      link="right_leg_pelvic_yaw_link" />
    <axis
      xyz="0 0 1" />
    <limit
      lower="-1.5708"
      upper="1.5708"
      effort="60"
      velocity="14" />
  </joint>
  <link
    name="right_leg_knee_pitch_link">
    <inertial>
      <origin
        xyz="0.0062807 0.003158 -0.1947"
        rpy="0 0 0" />
      <mass
        value="4.2982" />
      <inertia
        ixx="0.054098"
        ixy="-0.00011728"
        ixz="0.0018468"
        iyy="0.054533"
        iyz="0.002294"
        izz="0.0056954" />
    </inertial>
    <visual>
      <origin
        xyz="0 0 0"
        rpy="0 0 0" />
      <geometry>
        <mesh
          filename="../meshes/right_leg_knee_pitch_link.STL" />
      </geometry>
      <material
        name="">
        <color
          rgba="0.79216 0.81961 0.93333 1" />
      </material>
    </visual>
    <collision>
      <origin
        xyz="0 0 0"
        rpy="0 0 0" />
      <geometry>
        <mesh
          filename="../meshes/right_leg_knee_pitch_link.STL" />
      </geometry>
    </collision>
  </link>
  <joint
    name="right_leg_knee_pitch_joint"
    type="revolute">
    <origin
      xyz="-0.02 0 -0.2735"
      rpy="0 0 0" />
    <parent
      link="right_leg_pelvic_yaw_link" />
    <child
      link="right_leg_knee_pitch_link" />
    <axis
      xyz="0 1 0" />
    <limit
      lower="0"
      upper="2.5307"
      effort="150"
      velocity="14" />
  </joint>
  <link
    name="right_leg_ankle_pitch_link">
    <inertial>
      <origin
        xyz="0 -1.93E-06 0"
        rpy="0 0 0" />
      <mass
        value="0.057376" />
      <inertia
        ixx="1.172E-05"
        ixy="0"
        ixz="0"
        iyy="9.47E-06"
        iyz="0"
        izz="1.044E-05" />
    </inertial>
    <visual>
      <origin
        xyz="0 0 0"
        rpy="0 0 0" />
      <geometry>
        <mesh
          filename="../meshes/right_leg_ankle_pitch_link.STL" />
      </geometry>
      <material
        name="">
        <color
          rgba="0.79216 0.81961 0.93333 1" />
      </material>
    </visual>
    <collision>
      <origin
        xyz="0 0 0"
        rpy="0 0 0" />
      <geometry>
        <mesh
          filename="../meshes/right_leg_ankle_pitch_link.STL" />
      </geometry>
    </collision>
  </link>
  <joint
    name="right_leg_ankle_pitch_joint"
    type="revolute">
    <origin
      xyz="0 0 -0.453"
      rpy="0 0 0" />
    <parent
      link="right_leg_knee_pitch_link" />
    <child
      link="right_leg_ankle_pitch_link" />
    <axis
      xyz="0 1 0" />
    <limit
      lower="-0.87266"
      upper="0.50614"
      effort="60"
      velocity="14" />
  </joint>
  <link
    name="right_leg_ankle_roll_link">
    <inertial>
      <origin
        xyz="0.0231 -0.001227 -0.032967"
        rpy="0 0 0" />
      <mass
        value="1.0936" />
      <inertia
        ixx="0.0016821"
        ixy="-9.7E-05"
        ixz="-0.0002557"
        iyy="0.0065233"
        iyz="9.99E-06"
        izz="0.0070709" />
    </inertial>
    <visual>
      <origin
        xyz="0 0 0"
        rpy="0 0 0" />
      <geometry>
        <mesh
          filename="../meshes/right_leg_ankle_roll_link.STL" />
      </geometry>
      <material
        name="">
        <color
          rgba="0.79216 0.81961 0.93333 1" />
      </material>
    </visual>
    <collision>
      <origin
        xyz="0 0 0"
        rpy="0 0 0" />
      <geometry>
        <mesh
          filename="../meshes/right_leg_ankle_roll_link.STL" />
      </geometry>
    </collision>
  </link>
  <joint
    name="right_leg_ankle_roll_joint"
    type="revolute">
    <origin
      xyz="0 0 0"
      rpy="0 0 0" />
    <parent
      link="right_leg_ankle_pitch_link" />
    <child
      link="right_leg_ankle_roll_link" />
    <axis
      xyz="1 0 0" />
    <limit
      lower="-0.50614"
      upper="0.50614"
      effort="60"
      velocity="14" />
  </joint>
  <link
    name="waist_yaw_link">
    <inertial>
      <origin
        xyz="-0.011182 0.00019844 0.18439"
        rpy="0 0 0" />
      <mass
        value="11.255" />
      <inertia
        ixx="0.13369"
        ixy="0.0001217"
        ixz="-0.0059434"
        iyy="0.12551"
        iyz="1.709E-05"
        izz="0.073851" />
    </inertial>
    <visual>
      <origin
        xyz="0 0 0"
        rpy="0 0 0" />
      <geometry>
        <mesh
          filename="../meshes/waist_yaw_link_guitar.STL" />
      </geometry>
      <material
        name="">
        <color
          rgba="0.79216 0.81961 0.93333 1" />
      </material>
    </visual>
    <collision>
      <origin
        xyz="0 0 0"
        rpy="0 0 0" />
      <geometry>
        <mesh
          filename="../meshes/waist_yaw_link_guitar.STL" />
      </geometry>
    </collision>
  </link>
  <joint
    name="waist_yaw_joint"
    type="revolute">
    <origin
      xyz="0 0 0.15424"
      rpy="0 0 0" />
    <parent
      link="base_link" />
    <child
      link="waist_yaw_link" />
    <axis
      xyz="0 0 1" />
    <limit
      lower="-1.5708"
      upper="1.5708"
      effort="60"
      velocity="14" />
  </joint>
  <link
    name="head_yaw_link">
    <inertial>
      <origin
        xyz="-0.00045035 0.0020279 0.043829"
        rpy="0 0 0" />
      <mass
        value="0.53744" />
      <inertia
        ixx="0.0003913"
        ixy="-2.5E-06"
        ixz="1.181E-05"
        iyy="0.00032903"
        iyz="-8.01E-06"
        izz="0.00037805" />
    </inertial>
    <visual>
      <origin
        xyz="0 0 0"
        rpy="0 0 0" />
      <geometry>
        <mesh
          filename="../meshes/head_yaw_link.STL" />
      </geometry>
      <material
        name="">
        <color
          rgba="0.79216 0.81961 0.93333 1" />
      </material>
    </visual>
    <collision>
      <origin
        xyz="0 0 0"
        rpy="0 0 0" />
      <geometry>
        <mesh
          filename="../meshes/head_yaw_link.STL" />
      </geometry>
    </collision>
  </link>
  <joint
    name="head_yaw_joint"
    type="revolute">
    <origin
      xyz="0 0 0.36225"
      rpy="0 0 0" />
    <parent
      link="waist_yaw_link" />
    <child
      link="head_yaw_link" />
    <axis
      xyz="0 0 1" />
    <limit
      lower="-1.5708"
      upper="1.5708"
      effort="36"
      velocity="9.3" />
  </joint>
  <link
    name="head_pitch_link">
    <inertial>
      <origin
        xyz="0.028698 -0.00085276 0.085465"
        rpy="0 0 0" />
      <mass
        value="1.3964" />
      <inertia
        ixx="0.0046253"
        ixy="-2.19E-05"
        ixz="0.00054718"
        iyy="0.0051956"
        iyz="-6.616E-05"
        izz="0.0049992" />
    </inertial>
    <visual>
      <origin
        xyz="0 0 0"
        rpy="0 0 0" />
      <geometry>
        <mesh
          filename="../meshes/head_pitch_link.STL" />
      </geometry>
      <material
        name="">
        <color
          rgba="0.79216 0.81961 0.93333 1" />
      </material>
    </visual>
    <collision>
      <origin
        xyz="0 0 0"
        rpy="0 0 0" />
      <geometry>
        <mesh
          filename="../meshes/head_pitch_link.STL" />
      </geometry>
    </collision>
  </link>
  <joint
    name="head_pitch_joint"
    type="revolute">
    <origin
      xyz="0 0 0.045409"
      rpy="0 0 0" />
    <parent
      link="head_yaw_link" />
    <child
      link="head_pitch_link" />
    <axis
      xyz="0 1 0" />
    <limit
      lower="-0.2618"
      upper="0.5236"
      effort="36"
      velocity="9.3" />
  </joint>
  <link
    name="left_shoulder_pitch_link">
    <inertial>
      <origin
        xyz="0.004491 0.051064 1.17E-06"
        rpy="0 0 0" />
      <mass
        value="0.70124" />
      <inertia
        ixx="0.00048251"
        ixy="1.97E-05"
        ixz="4.6E-07"
        iyy="0.00035011"
        iyz="-2.2E-06"
        izz="0.00045997" />
    </inertial>
    <visual>
      <origin
        xyz="0 0 0"
        rpy="0 0 0" />
      <geometry>
        <mesh
          filename="../meshes/left_shoulder_pitch_link.STL" />
      </geometry>
      <material
        name="">
        <color
          rgba="0.792156862745098 0.819607843137255 0.933333333333333 1" />
      </material>
    </visual>
    <collision>
      <origin
        xyz="0 0 0"
        rpy="0 0 0" />
      <geometry>
        <mesh
          filename="../meshes/left_shoulder_pitch_link.STL" />
      </geometry>
    </collision>
  </link>
  <joint
    name="left_shoulder_pitch_joint"
    type="revolute">
    <origin
      xyz="0 0.145 0.2673"
      rpy="0 0 0" />
    <parent
      link="waist_yaw_link" />
    <child
      link="left_shoulder_pitch_link" />
    <axis
      xyz="0 1 0" />
    <limit
      lower="-3.22886"
      upper="1.60570"
      effort="75"
      velocity="12.2" />
  </joint>
  <link
    name="left_shoulder_roll_link">
    <inertial>
      <origin
        xyz="-0.0022055 0.00043559 -0.082734"
        rpy="0 0 0" />
      <mass
        value="0.67595" />
      <inertia
        ixx="0.0010679"
        ixy="1.49E-06"
        ixz="-0.00010051"
        iyy="0.0012151"
        iyz="2.353E-05"
        izz="0.00049051" />
    </inertial>
    <visual>
      <origin
        xyz="0 0 0"
        rpy="0 0 0" />
      <geometry>
        <mesh
          filename="../meshes/left_shoulder_roll_link.STL" />
      </geometry>
      <material
        name="">
        <color
          rgba="0.79216 0.81961 0.93333 1" />
      </material>
    </visual>
    <collision>
      <origin
        xyz="0 0 0"
        rpy="0 0 0" />
      <geometry>
        <mesh
          filename="../meshes/left_shoulder_roll_link.STL" />
      </geometry>
    </collision>
  </link>
  <joint
    name="left_shoulder_roll_joint"
    type="revolute">
    <!--
    <origin
      xyz="0 0.057 0"
      rpy="0.1745 0 0" />
      -->
    <origin
      xyz="0 0.057 0"
      rpy="0 0 0" />
    <parent
      link="left_shoulder_pitch_link" />
    <child
      link="left_shoulder_roll_link" />
    <axis
      xyz="1 0 0" />
    <limit
      lower="-0.34906585"
      upper="3.14159265"
      effort="75"
      velocity="12.2" />
  </joint>
  <link
    name="left_shoulder_yaw_link">
    <inertial>
      <origin
        xyz="-0.0025985 0.018021 -0.031346"
        rpy="0 0 0" />
      <mass
        value="0.17729" />
      <inertia
        ixx="0.0003193"
        ixy="-8.88E-06"
        ixz="-3E-07"
        iyy="0.00027717"
        iyz="8.333E-05"
        izz="0.00016534" />
    </inertial>
    <visual>
      <origin
        xyz="0 0 0"
        rpy="0 0 0" />
      <geometry>
        <mesh
          filename="../meshes/left_shoulder_yaw_link.STL" />
      </geometry>
      <material
        name="">
        <color
          rgba="0.79216 0.81961 0.93333 1" />
      </material>
    </visual>
    <collision>
      <origin
        xyz="0 0 0"
        rpy="0 0 0" />
      <geometry>
        <mesh
          filename="../meshes/left_shoulder_yaw_link.STL" />
      </geometry>
    </collision>
  </link>
  <joint
    name="left_shoulder_yaw_joint"
    type="revolute">
    <origin
      xyz="0 0 -0.1315"
      rpy="0 0 0" />
    <parent
      link="left_shoulder_roll_link" />
    <child
      link="left_shoulder_yaw_link" />
    <axis
      xyz="0 0 1" />
    <limit
      lower="-1.5708"
      upper="1.5708"
      effort="36"
      velocity="9.3" />
  </joint>
  <link
    name="left_elbow_pitch_link">
    <inertial>
      <origin
        xyz="-0.00063569 -0.0037979 -0.004468"
        rpy="0 0 0" />
      <mass
        value="0.6691" />
      <inertia
        ixx="0.00045264"
        ixy="1.547E-05"
        ixz="1.7E-07"
        iyy="0.00038999"
        iyz="1.727E-05"
        izz="0.00034119" />
    </inertial>
    <visual>
      <origin
        xyz="0 0 0"
        rpy="0 0 0" />
      <geometry>
        <mesh
          filename="../meshes/left_elbow_pitch_link.STL" />
      </geometry>
      <material
        name="">
        <color
          rgba="0.792156862745098 0.819607843137255 0.933333333333333 1" />
      </material>
    </visual>
    <collision>
      <origin
        xyz="0 0 0"
        rpy="0 0 0" />
      <geometry>
        <mesh
          filename="../meshes/left_elbow_pitch_link.STL" />
      </geometry>
    </collision>
  </link>
  <joint
    name="left_elbow_pitch_joint"
    type="revolute">
    <origin
      xyz="0 0 -0.081"
      rpy="0 0 0" />
    <parent
      link="left_shoulder_yaw_link" />
    <child
      link="left_elbow_pitch_link" />
    <axis
      xyz="0 1 0" />
    <limit
      lower="-2.26893"
      upper="0.34907"
      effort="75"
      velocity="12.2" />
  </joint>
  <link
    name="left_wrist_yaw_link">
    <inertial>
      <origin
        xyz="5.272E-05 0.008444 -0.064235"
        rpy="0 0 0" />
      <mass
        value="1.0429" />
      <inertia
        ixx="0.0016932"
        ixy="5.7E-07"
        ixz="2.12E-06"
        iyy="0.0015574"
        iyz="0.00026115"
        izz="0.00046784" />
    </inertial>
    <visual>
      <origin
        xyz="0 0 0"
        rpy="0 0 0" />
      <geometry>
        <mesh
          filename="../meshes/left_wrist_yaw_link.STL" />
      </geometry>
      <material
        name="">
        <color
          rgba="0.79216 0.81961 0.93333 1" />
      </material>
    </visual>
    <collision>
      <origin
        xyz="0 0 0"
        rpy="0 0 0" />
      <geometry>
        <mesh
          filename="../meshes/left_wrist_yaw_link.STL" />
      </geometry>
    </collision>
  </link>
  <joint
    name="left_wrist_yaw_joint"
    type="revolute">
    <origin
      xyz="0 0 -0.0525"
      rpy="0 0 0" />
    <parent
      link="left_elbow_pitch_link" />
    <child
      link="left_wrist_yaw_link" />
    <axis
      xyz="0 0 1" />
    <limit
      lower="-1.5708"
      upper="1.5708"
      effort="36"
      velocity="9.3" />
  </joint>
  <link
    name="left_wrist_pitch_link">
    <inertial>
      <origin
        xyz="0.0017421 0.0013674 0.00026392"
        rpy="0 0 0" />
      <mass
        value="0.46697" />
      <inertia
        ixx="0.00013428"
        ixy="-1.47E-06"
        ixz="-1.41E-06"
        iyy="0.00014007"
        iyz="2.8E-07"
        izz="0.00015006" />
    </inertial>
    <visual>
      <origin
        xyz="0 0 0"
        rpy="0 0 0" />
      <geometry>
        <mesh
          filename="../meshes/left_wrist_pitch_link.STL" />
      </geometry>
      <material
        name="">
        <color
          rgba="0.79216 0.81961 0.93333 1" />
      </material>
    </visual>
    <collision>
      <origin
        xyz="0 0 0"
        rpy="0 0 0" />
      <geometry>
        <mesh
          filename="../meshes/left_wrist_pitch_link.STL" />
      </geometry>
    </collision>
  </link>
  <joint
    name="left_wrist_pitch_joint"
    type="revolute">
    <origin
      xyz="0 0 -0.1665"
      rpy="0 0 0" />
    <parent
      link="left_wrist_yaw_link" />
    <child
      link="left_wrist_pitch_link" />
    <axis
      xyz="0 1 0" />
    <limit
      lower="-1.0472"
      upper="1.0472"
      effort="36"
      velocity="9.3" />
  </joint>
  <link
    name="left_wrist_roll_link">
    <inertial>
      <origin
        xyz="-0.0011269 0.00026424 -0.027639"
        rpy="0 0 0" />
      <mass
        value="0.11076" />
      <inertia
        ixx="9.193E-05"
        ixy="1.1E-06"
        ixz="-1.57E-06"
        iyy="0.00019499"
        iyz="-5.1E-07"
        izz="0.00013457" />
    </inertial>
    <visual>
      <origin
        xyz="0 0 0"
        rpy="0 0 0" />
      <geometry>
        <mesh
          filename="../meshes/left_wrist_roll_link.STL" />
      </geometry>
      <material
        name="">
        <color
          rgba="0.79216 0.81961 0.93333 1" />
      </material>
    </visual>
    <collision>
      <origin
        xyz="0 0 0"
        rpy="0 0 0" />
      <geometry>
        <mesh
          filename="../meshes/left_wrist_roll_link.STL" />
      </geometry>
    </collision>
  </link>
  <joint
    name="left_wrist_roll_joint"
    type="revolute">
    <origin
      xyz="0 0 0"
      rpy="0 0 0" />
    <parent
      link="left_wrist_pitch_link" />
    <child
      link="left_wrist_roll_link" />
    <axis
      xyz="1 0 0" />
    <limit
      lower="-1.5708"
      upper="1.0472"
      effort="36"
      velocity="9.3" />
  </joint>





































































  
    <!--right arm-->
  <link
    name="right_shoulder_pitch_link">
    <inertial>
      <origin
        xyz="0.0044088 -0.050926 -6.705E-05"
        rpy="0 0 0" />
      <mass
        value="0.70562" />
      <inertia
        ixx="0.00048946"
        ixy="-1.957E-05"
        ixz="6E-07"
        iyy="0.00035213"
        iyz="-4.7E-07"
        izz="0.00046784" />
    </inertial>
    <visual>
      <origin
        xyz="0 0 0"
        rpy="0 0 0" />
      <geometry>
        <mesh
          filename="../meshes/right_shoulder_pitch_link.STL" />
      </geometry>
      <material
        name="">
        <color
          rgba="0.79216 0.81961 0.93333 1" />
      </material>
    </visual>
    <collision>
      <origin
        xyz="0 0 0"
        rpy="0 0 0" />
      <geometry>
        <mesh
          filename="../meshes/right_shoulder_pitch_link.STL" />
      </geometry>
    </collision>
  </link>
  <joint
    name="right_shoulder_pitch_joint"
    type="revolute">
    <origin
      xyz="0 -0.145 0.2673"
      rpy="0 0 0" />
    <parent
      link="waist_yaw_link" />
    <child
      link="right_shoulder_pitch_link" />
    <axis
      xyz="0 1 0" />
    <limit
      lower="-3.22886"
      upper="1.60570"
      effort="75"
      velocity="12.2" />
  </joint>
  <link
    name="right_shoulder_roll_link">
    <inertial>
      <origin
        xyz="-0.0022151 -0.00044725 -0.082743"
        rpy="0 0 0" />
      <mass
        value="0.67591" />
      <inertia
        ixx="0.0010673"
        ixy="-1.24E-06"
        ixz="-0.00010009"
        iyy="0.0012144"
        iyz="-2.402E-05"
        izz="0.00049032" />
    </inertial>
    <visual>
      <origin
        xyz="0 0 0"
        rpy="0 0 0" />
      <geometry>
        <mesh
          filename="../meshes/right_shoulder_roll_link.STL" />
      </geometry>
      <material
        name="">
        <color
          rgba="0.79216 0.81961 0.93333 1" />
      </material>
    </visual>
    <collision>
      <origin
        xyz="0 0 0"
        rpy="0 0 0" />
      <geometry>
        <mesh
          filename="../meshes/right_shoulder_roll_link.STL" />
      </geometry>
    </collision>
  </link>
  <joint
    name="right_shoulder_roll_joint"
    type="revolute">
    <!--
    <origin
      xyz="0 -0.057 0"
      rpy="-0.1745 0 0" />
      -->
    <origin
      xyz="0 -0.057 0"
      rpy="0 0 0" />
    <parent
      link="right_shoulder_pitch_link" />
    <child
      link="right_shoulder_roll_link" />
    <axis
      xyz="1 0 0" />
    <limit
      lower="-3.14159265"
      upper="0.34906585"
      effort="75"
      velocity="12.2" />
  </joint>
  <link
    name="right_shoulder_yaw_link">
    <inertial>
      <origin
        xyz="-0.0026171 -0.018021 -0.031334"
        rpy="0 0 0" />
      <mass
        value="0.17728" />
      <inertia
        ixx="0.00031913"
        ixy="8.85E-06"
        ixz="-7.6E-07"
        iyy="0.00027698"
        iyz="-8.327E-05"
        izz="0.00016531" />
    </inertial>
    <visual>
      <origin
        xyz="0 0 0"
        rpy="0 0 0" />
      <geometry>
        <mesh
          filename="../meshes/right_shoulder_yaw_link.STL" />
      </geometry>
      <material
        name="">
        <color
          rgba="0.792156862745098 0.819607843137255 0.933333333333333 1" />
      </material>
    </visual>
    <collision>
      <origin
        xyz="0 0 0"
        rpy="0 0 0" />
      <geometry>
        <mesh
          filename="../meshes/right_shoulder_yaw_link.STL" />
      </geometry>
    </collision>
  </link>
  <joint
    name="right_shoulder_yaw_joint"
    type="revolute">
    <origin
      xyz="0 0 -0.1315"
      rpy="0 0 0" />
    <parent
      link="right_shoulder_roll_link" />
    <child
      link="right_shoulder_yaw_link" />
    <axis
      xyz="0 0 1" />
    <limit
      lower="-1.57079633"
      upper="1.57079633"
      effort="36"
      velocity="9.3" />
  </joint>
  <link
    name="right_elbow_pitch_link">
    <inertial>
      <origin
        xyz="-0.0010581 0.0021666 -0.0048302"
        rpy="0 0 0" />
      <mass
        value="0.69795" />
      <inertia
        ixx="0.00049558"
        ixy="-2.569E-05"
        ixz="1.31E-06"
        iyy="0.00040022"
        iyz="-2.646E-05"
        izz="0.00038606" />
    </inertial>
    <visual>
      <origin
        xyz="0 0 0"
        rpy="0 0 0" />
      <geometry>
        <mesh
          filename="../meshes/right_elbow_pitch_link.STL" />
      </geometry>
      <material
        name="">
        <color
          rgba="0.792156862745098 0.819607843137255 0.933333333333333 1" />
      </material>
    </visual>
    <collision>
      <origin
        xyz="0 0 0"
        rpy="0 0 0" />
      <geometry>
        <mesh
          filename="../meshes/right_elbow_pitch_link.STL" />
      </geometry>
    </collision>
  </link>
  <joint
    name="right_elbow_pitch_joint"
    type="revolute">
    <origin
      xyz="0 0 -0.081"
      rpy="0 0 0" />
    <parent
      link="right_shoulder_yaw_link" />
    <child
      link="right_elbow_pitch_link" />
    <axis
      xyz="0 1 0" />
    <limit
      lower="-2.26893"
      upper="0.34907"
      effort="75"
      velocity="12.2" />
  </joint>
  <link
    name="right_wrist_yaw_link">
    <inertial>
      <origin
        xyz="9.148E-05 -0.0071252 -0.062923"
        rpy="0 0 0" />
      <mass
        value="1.0027" />
      <inertia
        ixx="0.0015303"
        ixy="1.8E-07"
        ixz="2.82E-06"
        iyy="0.0014268"
        iyz="-0.00020725"
        izz="0.00039548" />
    </inertial>
    <visual>
      <origin
        xyz="0 0 0"
        rpy="0 0 0" />
      <geometry>
        <mesh
          filename="../meshes/right_wrist_yaw_link.STL" />
      </geometry>
      <material
        name="">
        <color
          rgba="0.79216 0.81961 0.93333 1" />
      </material>
    </visual>
    <collision>
      <origin
        xyz="0 0 0"
        rpy="0 0 0" />
      <geometry>
        <mesh
          filename="../meshes/right_wrist_yaw_link.STL" />
      </geometry>
    </collision>
  </link>
  <joint
    name="right_wrist_yaw_joint"
    type="revolute">
    <origin
      xyz="0 0 -0.0525"
      rpy="0 0 0" />
    <parent
      link="right_elbow_pitch_link" />
    <child
      link="right_wrist_yaw_link" />
    <axis
      xyz="0 0 1" />
    <limit
      lower="-1.57079633"
      upper="1.57079633"
      effort="36"
      velocity="9.3" />
  </joint>
  <link
    name="right_wrist_pitch_link">
    <inertial>
      <origin
        xyz="0.0023201 -0.0014143 0.00024603"
        rpy="0 0 0" />
      <mass
        value="0.47919" />
      <inertia
        ixx="0.00014279"
        ixy="1.07E-06"
        ixz="-1.38E-06"
        iyy="0.00015042"
        iyz="-2.9E-07"
        izz="0.0001623" />
    </inertial>
    <visual>
      <origin
        xyz="0 0 0"
        rpy="0 0 0" />
      <geometry>
        <mesh
          filename="../meshes/right_wrist_pitch_link.STL" />
      </geometry>
      <material
        name="">
        <color
          rgba="0.79216 0.81961 0.93333 1" />
      </material>
    </visual>
    <collision>
      <origin
        xyz="0 0 0"
        rpy="0 0 0" />
      <geometry>
        <mesh
          filename="../meshes/right_wrist_pitch_link.STL" />
      </geometry>
    </collision>
  </link>
  <joint
    name="right_wrist_pitch_joint"
    type="revolute">
    <origin
      xyz="0 0 -0.1665"
      rpy="0 0 0" />
    <parent
      link="right_wrist_yaw_link" />
    <child
      link="right_wrist_pitch_link" />
    <axis
      xyz="0 1 0" />
    <limit
      lower="-1.04719755"
      upper="1.04719755"
      effort="36"
      velocity="9.3" />
  </joint>
  <link
    name="right_wrist_roll_link">
    <inertial>
      <origin
        xyz="0.0020498 0.00015117 -0.02908"
        rpy="0 0 0" />
      <mass
        value="0.10176" />
      <inertia
        ixx="8.585E-05"
        ixy="6.3E-07"
        ixz="-7.22E-06"
        iyy="0.00017694"
        iyz="-2.9E-07"
        izz="0.00012118" />
    </inertial>
    <visual>
      <origin
        xyz="0 0 0"
        rpy="0 0 0" />
      <geometry>
        <mesh
          filename="../meshes/right_wrist_roll_link.STL" />
      </geometry>
      <material
        name="">
        <color
          rgba="0.79216 0.81961 0.93333 1" />
      </material>
    </visual>
    <collision>
      <origin
        xyz="0 0 0"
        rpy="0 0 0" />
      <geometry>
        <mesh
          filename="../meshes/right_wrist_roll_link.STL" />
      </geometry>
    </collision>
  </link>
  <joint
    name="right_wrist_roll_joint"
    type="revolute">
    <origin
      xyz="0 0 0"
      rpy="0 0 0" />
    <parent
      link="right_wrist_pitch_link" />
    <child
      link="right_wrist_roll_link" />
    <axis
      xyz="1 0 0" />
    <limit
      lower="-1.04719755"
      upper="1.57079633"
      effort="36"
      velocity="9.3" />
  </joint>



  
  
  
  
  
  
  
  
  
  
  
  
  
  
  
  
  
  
  <!--left hand-->
  <link
    name="left_palm_base_link">
    <inertial>
      <origin
        xyz="-0.00117 -0.00034371 0.051914"
        rpy="0 0 0" />
      <mass
        value="0.43097" />
      <inertia
        ixx="0.0005175"
        ixy="9.14E-06"
        ixz="3.04E-05"
        iyy="0.00036928"
        iyz="-1.49E-05"
        izz="0.000232" />
    </inertial>
    <visual>
      <origin
        xyz="0 0 0"
        rpy="0 0 0" />
      <geometry>
        <mesh
          filename="../meshes/left_palm_base_link.STL" />
      </geometry>
      <material
        name="">
        <color
          rgba="1 1 1 1" />
      </material>
    </visual>
    <collision>
      <origin
        xyz="0 0 0"
        rpy="0 0 0" />
      <geometry>
        <mesh
          filename="../meshes/left_palm_base_link.STL" />
      </geometry>
    </collision>
  </link>
  
  
  <joint
    name="left_hand_joint"
    type="fixed">
    <origin
      xyz="0 0 -0.0735"
      rpy="0 3.14 1.57" />
    <parent
      link="left_wrist_roll_link" />
    <child
      link="left_palm_base_link" />
    <!-- <axis
      xyz="0 0 1" />
    <limit
      lower="0"
      upper="0"
      effort="0"
      velocity="0" /> -->
  </joint>
  
  <link
    name="left_thumb_mcp_roll_link">
    <inertial>
      <origin
        xyz="0 -0.0049732 0.0010249"
        rpy="0 0 0" />
      <mass
        value="0.022768" />
      <inertia
        ixx="0.022768"
        ixy="0"
        ixz="0"
        iyy="1.39E-06"
        iyz="-7E-08"
        izz="2.01E-06" />
    </inertial>
    <visual>
      <origin
        xyz="0 0 0"
        rpy="0 0 0" />
      <geometry>
        <mesh
          filename="../meshes/left_thumb_mcp_roll_link.STL" />
      </geometry>
      <material
        name="">
        <color
          rgba="0.89804 0.91765 0.92941 1" />
      </material>
    </visual>
    <collision>
      <origin
        xyz="0 0 0"
        rpy="0 0 0" />
      <geometry>
        <mesh
          filename="../meshes/left_thumb_mcp_roll_link.STL" />
      </geometry>
    </collision>
  </link>
  <joint
    name="left_thumb_mcp_roll_joint"
    type="revolute">
    <origin
      xyz="0.01725 -0.019999 0.031069"
      rpy="0 0 0" />
    <parent
      link="left_palm_base_link" />
    <child
      link="left_thumb_mcp_roll_link" />
    <axis
      xyz="0 0 1" />
    <limit
      lower="0"
      upper="2.0944"
      effort="0"
      velocity="0" />
  </joint>
  <link
    name="left_thumb_mcp_pitch_link">
    <inertial>
      <origin
        xyz="-5.03E-06 -0.02379416 0.00499973"
        rpy="0 0 0" />
      <mass
        value="0.02573006" />
      <inertia
        ixx="5.72E-06"
        ixy="0"
        ixz="0"
        iyy="1.75E-06"
        iyz="1.45E-06"
        izz="5.48E-06" />
    </inertial>
    <visual>
      <origin
        xyz="0 0 0"
        rpy="0 0 0" />
      <geometry>
        <mesh
          filename="../meshes/left_thumb_mcp_pitch_link.STL" />
      </geometry>
      <material
        name="">
        <color
          rgba="0.89804 0.91765 0.92941 1" />
      </material>
    </visual>
    <collision>
      <origin
        xyz="0 0 0"
        rpy="0 0 0" />
      <geometry>
        <mesh
          filename="../meshes/left_thumb_mcp_pitch_link.STL" />
      </geometry>
    </collision>
  </link>
  <joint
    name="left_thumb_mcp_pitch_joint"
    type="revolute">
    <origin
      xyz="0 -0.0105 0.00165"
      rpy="0 0 0" />
    <parent
      link="left_thumb_mcp_roll_link" />
    <child
      link="left_thumb_mcp_pitch_link" />
    <axis
      xyz="-1 0 0" />
    <limit
      lower="0"
      upper="0.5236"
      effort="0"
      velocity="0" />
  </joint>
  <link
    name="left_thumb_dip_link">
    <inertial>
      <origin
        xyz="1.38E-05 -0.02043268 0.00858416"
        rpy="0 0 0" />
      <mass
        value="0.01370954" />
      <inertia
        ixx="2.57E-06"
        ixy="0"
        ixz="0"
        iyy="9.2E-07"
        iyz="8.3E-07"
        izz="2.29E-06" />
    </inertial>
    <visual>
      <origin
        xyz="0 0 0"
        rpy="0 0 0" />
      <geometry>
        <mesh
          filename="../meshes/left_thumb_dip_link.STL" />
      </geometry>
      <material
        name="">
        <color
          rgba="0.29804 0.29804 0.29804 1" />
      </material>
    </visual>
    <collision>
      <origin
        xyz="0 0 0"
        rpy="0 0 0" />
      <geometry>
        <mesh
          filename="../meshes/left_thumb_dip_link.STL" />
      </geometry>
    </collision>
  </link>
  <joint
    name="left_thumb_dip_joint"
    type="revolute">
    <origin
      xyz="0 -0.0404571702173548 0.0113233112649935"
      rpy="0 0 0" />
    <parent
      link="left_thumb_mcp_pitch_link" />
    <child
      link="left_thumb_dip_link" />
    <axis
      xyz="-1 0 0" />
    <limit
      lower="0"
      upper="1.5708"
      effort="0"
      velocity="0" />
  </joint>
  
  <link
    name="left_index_mcp_link">
    <inertial>
      <origin
        xyz="-0.00146214 -0.0628 0.01905806"
        rpy="0 0 0" />
      <mass
        value="0.01930995" />
      <inertia
        ixx="4.71E-06"
        ixy="0"
        ixz="2E-08"
        iyy="4.6E-06"
        iyz="6.2E-07"
        izz="7.5E-07" />
    </inertial>
    <visual>
      <origin
        xyz="0 0 0"
        rpy="0 0 0" />
      <geometry>
        <mesh
          filename="../meshes/left_index_mcp_link.STL" />
      </geometry>
      <material
        name="">
        <color
          rgba="0.79216 0.81961 0.93333 1" />
      </material>
    </visual>
    <collision>
      <origin
        xyz="0 0 0"
        rpy="0 0 0" />
      <geometry>
        <mesh
          filename="../meshes/left_index_mcp_link.STL" />
      </geometry>
    </collision>
  </link>
  <joint
    name="left_index_mcp_joint"
    type="revolute">
    <origin
      xyz="0.00025022 -0.027833 0.093267"
      rpy="0.07854 0 0" />
    <parent
      link="left_palm_base_link" />
    <child
      link="left_index_mcp_link" />
    <axis
      xyz="0 1 0" />
    <limit
      lower="0"
      upper="1.5708"
      effort="0"
      velocity="0" />
  </joint>
  <link
    name="left_index_dip_link">
    <inertial>
      <origin
        xyz="-0.00045613 3.48E-05 0.01776918"
        rpy="0 0 0" />
      <mass
        value="0.01333774" />
      <inertia
        ixx="3.06E-06"
        ixy="0"
        ixz="-6E-08"
        iyy="3.04E-06"
        iyz="0"
        izz="3.8E-07" />
    </inertial>
    <visual>
      <origin
        xyz="0 0 0"
        rpy="0 0 0" />
      <geometry>
        <mesh
          filename="../meshes/left_index_dip_link.STL" />
      </geometry>
      <material
        name="">
        <color
          rgba="0.79216 0.81961 0.93333 1" />
      </material>
    </visual>
    <collision>
      <origin
        xyz="0 0 0"
        rpy="0 0 0" />
      <geometry>
        <mesh
          filename="../meshes/left_index_dip_link.STL" />
      </geometry>
    </collision>
  </link>
  <joint
    name="left_index_dip_joint"
    type="revolute">
    <origin
      xyz="-0.000999999999798432 0 0.0420000000000047"
      rpy="0 0 0" />
    <parent
      link="left_index_mcp_link" />
    <child
      link="left_index_dip_link" />
    <axis
      xyz="0 1 0" />
    <limit
      lower="0"
      upper="1.5708"
      effort="0"
      velocity="0" />
  </joint>
  
  <link
    name="left_middle_mcp_link">
    <inertial>
      <origin
        xyz="-0.00163537 5.225E-05 0.02320785"
        rpy="0 0 0" />
      <mass
        value="0.02127795" />
      <inertia
        ixx="6.35E-06"
        ixy="0"
        ixz="5E-08"
        iyy="6.35E-06"
        iyz="0"
        izz="7.4E-07" />
    </inertial>
    <visual>
      <origin
        xyz="0 0 0"
        rpy="0 0 0" />
      <geometry>
        <mesh
          filename="../meshes/left_middle_mcp_link.STL" />
      </geometry>
      <material
        name="">
        <color
          rgba="0.29804 0.29804 0.29804 1" />
      </material>
    </visual>
    <collision>
      <origin
        xyz="0 0 0"
        rpy="0 0 0" />
      <geometry>
        <mesh
          filename="../meshes/left_middle_mcp_link.STL" />
      </geometry>
    </collision>
  </link>
  <joint
    name="left_middle_mcp_joint"
    type="revolute">
    <origin
      xyz="0.00025022 -0.0079444 0.094317"
      rpy="0.02618 0 0" />
    <parent
      link="left_palm_base_link" />
    <child
      link="left_middle_mcp_link" />
    <axis
      xyz="0 1 0" />
    <limit
      lower="0"
      upper="1.5708"
      effort="0"
      velocity="0" />
  </joint>
  <link
    name="left_middle_dip_link">
    <inertial>
      <origin
        xyz="-0.00045613 3.48E-05 0.01776918"
        rpy="0 0 0" />
      <mass
        value="0.01333774" />
      <inertia
        ixx="3.06E-06"
        ixy="0"
        ixz="-6E-08"
        iyy="3.04E-06"
        iyz="0"
        izz="3.8E-07" />
    </inertial>
    <visual>
      <origin
        xyz="0 0 0"
        rpy="0 0 0" />
      <geometry>
        <mesh
          filename="../meshes/left_middle_dip_link.STL" />
      </geometry>
      <material
        name="">
        <color
          rgba="0.79216 0.81961 0.93333 1" />
      </material>
    </visual>
    <collision>
      <origin
        xyz="0 0 0"
        rpy="0 0 0" />
      <geometry>
        <mesh
          filename="../meshes/left_middle_dip_link.STL" />
      </geometry>
    </collision>
  </link>
  <joint
    name="left_middle_dip_joint"
    type="revolute">
    <origin
      xyz="-0.00125209669046785 0 0.0471448973036052"
      rpy="0 0 0" />
    <parent
      link="left_middle_mcp_link" />
    <child
      link="left_middle_dip_link" />
    <axis
      xyz="0 1 0" />
    <limit
      lower="0"
      upper="1.5708"
      effort="0"
      velocity="0" />
  </joint>
  
  <link
    name="left_ring_mcp_link">
    <inertial>
      <origin
        xyz="-0.00146214 -0.0628 0.01905806"
        rpy="0 0 0" />
      <mass
        value="0.01930995" />
      <inertia
        ixx="4.71E-06"
        ixy="0"
        ixz="2E-08"
        iyy="4.6E-06"
        iyz="6.2E-07"
        izz="7.5E-07" />
    </inertial>
    <visual>
      <origin
        xyz="0 0 0"
        rpy="0 0 0" />
      <geometry>
        <mesh
          filename="../meshes/left_ring_mcp_link.STL" />
      </geometry>
      <material
        name="">
        <color
          rgba="0.79216 0.81961 0.93333 1" />
      </material>
    </visual>
    <collision>
      <origin
        xyz="0 0 0"
        rpy="0 0 0" />
      <geometry>
        <mesh
          filename="../meshes/left_ring_mcp_link.STL" />
      </geometry>
    </collision>
  </link>
  <joint
    name="left_ring_mcp_joint"
    type="revolute">
    <origin
      xyz="0.00025022 0.011946 0.093314"
      rpy="-0.02618 0 0" />
    <parent
      link="left_palm_base_link" />
    <child
      link="left_ring_mcp_link" />
    <axis
      xyz="0 1 0" />
    <limit
      lower="0"
      upper="1.5708"
      effort="0"
      velocity="0" />
  </joint>
  <link
    name="left_ring_dip_link">
    <inertial>
      <origin
        xyz="-0.00045613 3.48E-05 0.01776918"
        rpy="0 0 0" />
      <mass
        value="0.01333774" />
      <inertia
        ixx="3.06E-06"
        ixy="0"
        ixz="-6E-08"
        iyy="3.04E-06"
        iyz="0"
        izz="3.8E-07" />
    </inertial>
    <visual>
      <origin
        xyz="0 0 0"
        rpy="0 0 0" />
      <geometry>
        <mesh
          filename="../meshes/left_ring_dip_link.STL" />
      </geometry>
      <material
        name="">
        <color
          rgba="0.79216 0.81961 0.93333 1" />
      </material>
    </visual>
    <collision>
      <origin
        xyz="0 0 0"
        rpy="0 0 0" />
      <geometry>
        <mesh
          filename="../meshes/left_ring_dip_link.STL" />
      </geometry>
    </collision>
  </link>
  <joint
    name="left_ring_dip_joint"
    type="revolute">
    <origin
      xyz="-0.000999999999795606 0 0.0420000000000048"
      rpy="0 0 0" />
    <parent
      link="left_ring_mcp_link" />
    <child
      link="left_ring_dip_link" />
    <axis
      xyz="0 1 0" />
    <limit
      lower="0"
      upper="1.5708"
      effort="0"
      velocity="0" />
  </joint>
  
  <link
    name="left_pinky_mcp_link">
    <inertial>
      <origin
        xyz="-0.00146313 4.158E-05 0.01853468"
        rpy="0 0 0" />
      <mass
        value="0.01761671" />
      <inertia
        ixx="3.75E-06"
        ixy="0"
        ixz="3E-08"
        iyy="3.73E-06"
        iyz="0"
        izz="5.7E-07" />
    </inertial>
    <visual>
      <origin
        xyz="0 0 0"
        rpy="0 0 0" />
      <geometry>
        <mesh
          filename="../meshes/left_pinky_mcp_link.STL" />
      </geometry>
      <material
        name="">
        <color
          rgba="1 1 1 1" />
      </material>
    </visual>
    <collision>
      <origin
        xyz="0 0 0"
        rpy="0 0 0" />
      <geometry>
        <mesh
          filename="../meshes/left_pinky_mcp_link.STL" />
      </geometry>
    </collision>
  </link>
  <joint
    name="left_pinky_mcp_joint"
    type="revolute">
    <origin
      xyz="0.00025022 0.031624 0.090267"
      rpy="-0.07854 0 0" />
    <parent
      link="left_palm_base_link" />
    <child
      link="left_pinky_mcp_link" />
    <axis
      xyz="0 1 0" />
    <limit
      lower="0"
      upper="1.5708"
      effort="0"
      velocity="0" />
  </joint>
  <link
    name="left_pinky_dip_link">
    <inertial>
      <origin
        xyz="-0.00045613 3.48E-05 0.01776918"
        rpy="0 0 0" />
      <mass
        value="0.01333774" />
      <inertia
        ixx="3.06E-06"
        ixy="0"
        ixz="-6E-08"
        iyy="3.04E-06"
        iyz="0"
        izz="3.8E-07" />
    </inertial>
    <visual>
      <origin
        xyz="0 0 0"
        rpy="0 0 0" />
      <geometry>
        <mesh
          filename="../meshes/left_pinky_dip_link.STL" />
      </geometry>
      <material
        name="">
        <color
          rgba="0.79216 0.81961 0.93333 1" />
      </material>
    </visual>
    <collision>
      <origin
        xyz="0 0 0"
        rpy="0 0 0" />
      <geometry>
        <mesh
          filename="../meshes/left_pinky_dip_link.STL" />
      </geometry>
    </collision>
  </link>
  <joint
    name="left_pinky_dip_joint"
    type="revolute">
    <origin
      xyz="-0.000999999999988846 0 0.0369999999999856"
      rpy="0 0 0" />
    <parent
      link="left_pinky_mcp_link" />
    <child
      link="left_pinky_dip_link" />
    <axis
      xyz="0 1 0" />
    <limit
      lower="0"
      upper="1.5708"
      effort="0"
      velocity="0" />
  </joint>



  
  
  
  
  
  
  
  

  <!--right hand-->
  <link
    name="right_palm_base_link">
    
    <inertial>
      <origin xyz="0.01499498 0.00541856 0.06398785"  rpy="0 0 0" />
      <mass value="0.14" />
      <inertia
        ixx="0.00082104"
        ixy="-0.00003638"
        ixz="-0.00016628"
        iyy="0.00086679"
        iyz="-0.00004756"
        izz="0.00019803" />
    </inertial>
    
    <!--
    <inertial>
      <origin
        xyz="-7.23904362592994E-05 0.00244793375456751 0.0444931429093674"
        rpy="0 0 0" />
      <mass
        value="0.119458442358977" />
      <inertia
        ixx="0.000182894595109089"
        ixy="3.42270042423038E-07"
        ixz="-1.39343672308657E-06"
        iyy="0.000110853008409238"
        iyz="1.78076033006766E-06"
        izz="7.96894353657269E-05" />
    </inertial>
    -->
    <visual>
      <origin
        xyz="0 0 0"
        rpy="0 0 0" />
      <geometry>
        <mesh
          filename="../meshes/right_fake_hand_link.STL" />
      </geometry>
      <material
        name="">
        <color
          rgba="0.752941176470588 0.752941176470588 0.752941176470588 1" />
      </material>
    </visual>
    <collision>
      <origin
        xyz="0 0 0"
        rpy="0 0 0" />
      <geometry>
        <mesh
          filename="../meshes/right_fake_hand_link.STL" />
      </geometry>
    </collision>
  </link>
  
  <joint
    name="right_hand_joint"
    type="fixed">
    <origin
      xyz="0 0 -0.0735"
      rpy="0 3.14 -1.57" />
    <parent
      link="right_wrist_roll_link" />
    <child
      link="right_palm_base_link" />
    <!-- <axis
      xyz="0 0 1" />
    <limit
      lower="0"
      upper="0"
      effort="0"
      velocity="0" /> -->
  </joint>
  
  
  
  
</robot>
